
Due to MODULEPATH changes, the following have been reloaded:
  1) openmpi/2.1.1

Python 3.5.4
../PreprocessedData/preprocessedForCNN/299 x 299/imgData_(299, 299, 3)_test.npy
../PreprocessedData/preprocessedForCNN/299 x 299/targetData_(299, 299, 3)_test.csv
../modelOutput/compareModels2/VGG16_dataAug_False2019-06-05_15_46_default_224_noprep/VGG16.hdf5
_testSet_
2019-06-05 19:20:49.400390: I tensorflow/core/common_runtime/gpu/gpu_device.cc:1432] Found device 0 with properties: 
name: Tesla P100-PCIE-12GB major: 6 minor: 0 memoryClockRate(GHz): 1.3285
pciBusID: 0000:04:00.0
totalMemory: 11.91GiB freeMemory: 11.63GiB
2019-06-05 19:20:49.400581: I tensorflow/core/common_runtime/gpu/gpu_device.cc:1511] Adding visible gpu devices: 0
2019-06-05 19:20:49.763557: I tensorflow/core/common_runtime/gpu/gpu_device.cc:982] Device interconnect StreamExecutor with strength 1 edge matrix:
2019-06-05 19:20:49.763711: I tensorflow/core/common_runtime/gpu/gpu_device.cc:988]      0 
2019-06-05 19:20:49.763751: I tensorflow/core/common_runtime/gpu/gpu_device.cc:1001] 0:   N 
2019-06-05 19:20:49.764083: I tensorflow/core/common_runtime/gpu/gpu_device.cc:1115] Created TensorFlow device (/job:localhost/replica:0/task:0/device:GPU:0 with 11251 MB memory) -> physical GPU (device: 0, name: Tesla P100-PCIE-12GB, pci bus id: 0000:04:00.0, compute capability: 6.0)
2019-06-05 19:20:49.764604: I tensorflow/core/common_runtime/process_util.cc:69] Creating new thread pool with default inter op setting: 2. Tune using inter_op_parallelism_threads for best performance.
Using TensorFlow backend.
Traceback (most recent call last):
  File "./modelPred.py", line 125, in <module>
    args.note)
  File "./modelPred.py", line 82, in main_driver
    verbose=1)
  File "/home/amourav/tensorflow/lib/python3.5/site-packages/keras/engine/training.py", line 1149, in predict
    x, _, _ = self._standardize_user_data(x)
  File "/home/amourav/tensorflow/lib/python3.5/site-packages/keras/engine/training.py", line 751, in _standardize_user_data
    exception_prefix='input')
  File "/home/amourav/tensorflow/lib/python3.5/site-packages/keras/engine/training_utils.py", line 138, in standardize_input_data
    str(data_shape))
ValueError: Error when checking input: expected input_1 to have shape (224, 224, 3) but got array with shape (299, 299, 3)
trn path: ../PreprocessedData/preprocessedForCNN/299 x 299/imgData_(299, 299, 3)_test.npy
